Failure # 1 (occurred at 2023-10-18_15-03-47)
[36mray::ImplicitFunc.train()[39m (pid=7692, ip=171.65.93.126, actor_id=fc1e0240a66b89e57268b7ce01000000, repr=objective)
  File "/home/nrubio/anaconda3/envs/tf-gpu-cuda10/lib/python3.9/site-packages/ray/tune/trainable/trainable.py", line 400, in train
    raise skipped from exception_cause(skipped)
  File "/home/nrubio/anaconda3/envs/tf-gpu-cuda10/lib/python3.9/site-packages/ray/air/_internal/util.py", line 91, in run
    self._ret = self._target(*self._args, **self._kwargs)
  File "/home/nrubio/anaconda3/envs/tf-gpu-cuda10/lib/python3.9/site-packages/ray/tune/trainable/function_trainable.py", line 383, in <lambda>
    training_func=lambda: self._trainable_func(self.config),
  File "/home/nrubio/anaconda3/envs/tf-gpu-cuda10/lib/python3.9/site-packages/ray/tune/trainable/function_trainable.py", line 822, in _trainable_func
    output = fn()
  File "/home/nrubio/Desktop/junction_pressure_differentials/util/regression/neural_network/nn_opt.py", line 21, in objective
    train_mse, val_mse, model_name = train_and_val_gnn(anatomy = "Aorta_rand", num_geos = 110,  seed = 0, unsteady = True, config = config)
  File "/home/nrubio/Desktop/junction_pressure_differentials/util/regression/neural_network/launch_training.py", line 78, in train_and_val_gnn
    save_model(gnn_model, model_name)
  File "/home/nrubio/Desktop/junction_pressure_differentials/util/regression/neural_network/launch_training.py", line 31, in save_model
    os.mkdir(f"results/models/neural_network/steady/{model_name}")
FileNotFoundError: [Errno 2] No such file or directory: 'results/models/neural_network/steady/0_hl_17_lsmlp_0_1_lr_0_007_lrd_1e-05_wd_bs_40_nepochs_200_seed_0_geos_110'
