Failure # 1 (occurred at 2023-12-25_13-24-59)
[36mray::ImplicitFunc.train()[39m (pid=25430, ip=171.65.93.126, actor_id=06c5411bdb4c745da16b5e2001000000, repr=objective)
  File "/home/nrubio/anaconda3/envs/tf-gpu-cuda10/lib/python3.9/site-packages/ray/tune/trainable/trainable.py", line 400, in train
    raise skipped from exception_cause(skipped)
  File "/home/nrubio/anaconda3/envs/tf-gpu-cuda10/lib/python3.9/site-packages/ray/air/_internal/util.py", line 91, in run
    self._ret = self._target(*self._args, **self._kwargs)
  File "/home/nrubio/anaconda3/envs/tf-gpu-cuda10/lib/python3.9/site-packages/ray/tune/trainable/function_trainable.py", line 383, in <lambda>
    training_func=lambda: self._trainable_func(self.config),
  File "/home/nrubio/anaconda3/envs/tf-gpu-cuda10/lib/python3.9/site-packages/ray/tune/trainable/function_trainable.py", line 822, in _trainable_func
    output = fn()
  File "/home/nrubio/Desktop/junction_pressure_differentials/util/regression/neural_network/nn_opt.py", line 22, in objective
    train_mse, val_mse, model_name = train_and_val_gnn(anatomy = "Aorta_rand", num_geos = 110,  seed = 0, unsteady = True, unsteady_opt = False, config = config)
  File "/home/nrubio/Desktop/junction_pressure_differentials/util/regression/neural_network/launch_training.py", line 82, in train_and_val_gnn
    gnn_model = GraphNet(anatomy, network_params, unsteady, unsteady_opt)
  File "/home/nrubio/Desktop/junction_pressure_differentials/util/regression/neural_network/graphnet_nn.py", line 59, in __init__
    self.steady_model = tf.keras.models.load_model("results/models/neural_network/steady/"+steady_model_name, compile=True)
  File "/home/nrubio/anaconda3/envs/tf-gpu-cuda10/lib/python3.9/site-packages/tensorflow/python/keras/saving/save.py", line 211, in load_model
    loader_impl.parse_saved_model(filepath)
  File "/home/nrubio/anaconda3/envs/tf-gpu-cuda10/lib/python3.9/site-packages/tensorflow/python/saved_model/loader_impl.py", line 111, in parse_saved_model
    raise IOError("SavedModel file does not exist at: %s/{%s|%s}" %
OSError: SavedModel file does not exist at: results/models/neural_network/steady/1_hl_52_lsmlp_0_0931_lr_0_008_lrd_1e-05_wd_bs_29_nepochs_300_seed_0_geos_110_steady/{saved_model.pbtxt|saved_model.pb}
