Failure # 1 (occurred at 2023-10-18_15-01-23)
[36mray::ImplicitFunc.train()[39m (pid=6046, ip=171.65.93.126, actor_id=42ad14d80a3f931ab9fb30f601000000, repr=objective)
  File "/home/nrubio/anaconda3/envs/tf-gpu-cuda10/lib/python3.9/site-packages/ray/tune/trainable/trainable.py", line 400, in train
    raise skipped from exception_cause(skipped)
  File "/home/nrubio/anaconda3/envs/tf-gpu-cuda10/lib/python3.9/site-packages/ray/air/_internal/util.py", line 91, in run
    self._ret = self._target(*self._args, **self._kwargs)
  File "/home/nrubio/anaconda3/envs/tf-gpu-cuda10/lib/python3.9/site-packages/ray/tune/trainable/function_trainable.py", line 383, in <lambda>
    training_func=lambda: self._trainable_func(self.config),
  File "/home/nrubio/anaconda3/envs/tf-gpu-cuda10/lib/python3.9/site-packages/ray/tune/trainable/function_trainable.py", line 822, in _trainable_func
    output = fn()
  File "/home/nrubio/Desktop/junction_pressure_differentials/util/regression/neural_network/nn_opt.py", line 21, in objective
    train_mse, val_mse, model_name = train_and_val_gnn(anatomy = "Aorta_rand", num_geos = 110,  seed = 0, unsteady = True, config = config)
  File "/home/nrubio/Desktop/junction_pressure_differentials/util/regression/neural_network/launch_training.py", line 70, in train_and_val_gnn
    gnn_model, val_mse, train_mse = train_gnn_model(anatomy,
  File "/home/nrubio/Desktop/junction_pressure_differentials/util/regression/neural_network/training_nn.py", line 187, in train_gnn_model
    plt.savefig("results/training_plots/" + model_name + "mse_over_epochs.png", dpi=1200, bbox_inches='tight', transparent=False)
  File "/home/nrubio/anaconda3/envs/tf-gpu-cuda10/lib/python3.9/site-packages/matplotlib/pyplot.py", line 977, in savefig
    res = fig.savefig(*args, **kwargs)
  File "/home/nrubio/anaconda3/envs/tf-gpu-cuda10/lib/python3.9/site-packages/matplotlib/figure.py", line 3058, in savefig
    self.canvas.print_figure(fname, **kwargs)
  File "/home/nrubio/anaconda3/envs/tf-gpu-cuda10/lib/python3.9/site-packages/matplotlib/backend_bases.py", line 2319, in print_figure
    result = print_method(
  File "/home/nrubio/anaconda3/envs/tf-gpu-cuda10/lib/python3.9/site-packages/matplotlib/backend_bases.py", line 1648, in wrapper
    return func(*args, **kwargs)
  File "/home/nrubio/anaconda3/envs/tf-gpu-cuda10/lib/python3.9/site-packages/matplotlib/_api/deprecation.py", line 415, in wrapper
    return func(*inner_args, **inner_kwargs)
  File "/home/nrubio/anaconda3/envs/tf-gpu-cuda10/lib/python3.9/site-packages/matplotlib/backends/backend_agg.py", line 541, in print_png
    mpl.image.imsave(
  File "/home/nrubio/anaconda3/envs/tf-gpu-cuda10/lib/python3.9/site-packages/matplotlib/image.py", line 1675, in imsave
    image.save(fname, **pil_kwargs)
  File "/home/nrubio/anaconda3/envs/tf-gpu-cuda10/lib/python3.9/site-packages/PIL/Image.py", line 2317, in save
    fp = builtins.open(filename, "w+b")
FileNotFoundError: [Errno 2] No such file or directory: 'results/training_plots/2_hl_33_lsmlp_0_1_lr_0_002_lrd_1e-05_wd_bs_40_nepochs_200_seed_0_geos_110mse_over_epochs.png'
